2020-11-26 10:41:58.964 | ERROR    | __main__:<module>:21 - An error has been caught in function '<module>', process 'MainProcess' (9080), thread 'MainThread' (2276):
Traceback (most recent call last):

> File "E:/pyAutoTest/pyTest/TestDemo.py", line 21, in <module>
    a = my_function(1,1,-2)
        ©¸ <function my_function at 0x000001ED4F885048>

  File "E:/pyAutoTest/pyTest/TestDemo.py", line 17, in my_function
    a = 1/(x+y+z)
           ©¦ ©¦ ©¸ -2
           ©¦ ©¸ 1
           ©¸ 1

ZeroDivisionError: division by zero
